Workbook
Name accountnumber: [1]Accounts!$C$2:$D$1560
Name condensed: 'Product List'!#REF!
Name coreprices: 'Price List'!$C$9:$AC$16
Name currency: [1]Accounts!$E$17:$E$20
Name customerdiscount: [1]Accounts!$E$4:$I$9
Name customers: [1]Accounts!$C$2:$C$1560
Name distprice: '[2]Product list'!$B$1:$R$65536
Name MGPcore: 'Price List'!$C$9:$C$16
Name MGPcover: 'Price List'!$C$20:$C$28
Name MGPextras: 'Price List'!$C$42:$C$71
Name polyprice: 'Price List'!$J$18:$AA$20
Name pricefile: 'Product List'!$C:$E
Name product_group_discount: '[1]New Quote Discount'!$A$6:$C$12
Name Retail: 'Product List'!$C$5:$E$1166

Sheet Price List
C2: Marlow Ropes Ltd | F2: N/A | H2: MORFRAC | V2: EUR
S4: #(515): Invalid Customer
C5: Grand Prix Series Price List 2019 | S5: b
C7: CORE | D7: Rope Dia | H7: 4mm | I7: 5 | J7: 6 | K7: 7 | L7: 8 | M7: 9 | N7: 10 | O7: 11 | P7: 12 | Q7: 13 | R7: 14 | T7: 15 | U7: 16 | V7: 18 | W7: 20 | X7: 22 | Y7: 23 | Z7: 24 | AA7: 26 | AB7: 28 | AC7: 30
D8: Core Dia | G8: 2.5 | H8: 3 | I8: 3.5 | J8: 4 | K8: 5 | L8: 6 | M8: 6.5 | N8: 7 | O8: 8 | P8: 9 | R8: 10 | U8: 11 | V8: 13 | W8: 15 | X8: 16 | Y8: 17 | Z8: 18 | AA8: 19 | AB8: 20 | AC8: 22
C9: D12 78 | G9: 0.588 | H9: 0.942 | I9: 1.092 | J9: 1.194 | K9: 1.764 | L9: 2.544 | M9: 2.832 | N9: 3.126 | O9: 3.45 | P9: 3.78 | Q9: - | R9: 4.854 | S9: - | T9: - | U9: 5.928 | V9: 8.04 | W9: 10.278 | X9: 13.2 | Y9: 14.382 | Z9: 14.794931 | AA9: 17.695764 | AB9: 20.224812 | AC9: 23.405052
C10: D12 99 | G10: 0.852 | H10: 1.224 | I10: 1.4 | J10: 1.542 | K10: 2.28 | L10: 3.288 | M10: 3.654 | N10: 4.032 | O10: 4.506 | P10: 4.884 | Q10: - | R10: 6.276 | S10: - | T10: - | U10: 7.662 | V10: 10.38 | W10: 13.266 | X10: 15.738 | Y10: - | Z10: 20.064 | AA10: 24.72 | AB10: 26.750339 | AC10: 31.722
C11: D12 Max 78 | G11: 1.092 | H11: 1.152 | I11: - | J11: 1.524 | K11: 2.046 | L11: 2.994 | M11: - | N11: 4.176 | O11: 5.55 | P11: 6.33 | Q11: - | R11: 7.59 | S11: - | T11: - | U11: 8.856 | V11: 12.3 | W11: 15.936 | X11: - | Y11: 21.486 | Z11: - | AA11: - | AB11: - | AC11: -
C12: D12 Max 99 | G12: 1.422 | H12: 1.494 | I12: - | J12: 1.992 | K12: 2.49 | L12: 3.876 | M12: - | N12: 5.388 | O12: 6.774 | P12: 8.184 | Q12: - | R12: 9.792 | S12: - | T12: - | U12: 11.424 | V12: 15.888 | W12: 20.358 | X12: - | Y12: 27.648 | Z12: - | AA12: - | AB12: - | AC12: -
C13: M-Rig Max | G13: 1.272 | H13: 1.428 | I13: - | J13: 1.908 | K13: 2.382 | L13: 3.702 | M13: - | N13: 5.148 | O13: 6.474 | P13: 7.818 | Q13: - | R13: 9.366 | S13: - | T13: - | U13: 10.926 | V13: - | W13: 19.255424 | X13: - | Y13: 26.16392 | Z13: - | AA13: - | AB13: - | AC13: -
C14: T12 | G14: - | H14: 0.768 | I14: - | J14: 1.578 | K14: 1.842 | L14: 2.178 | M14: - | N14: 3.06 | O14: 3.06 | P14: - | Q14: - | R14: 5.13 | S14: - | T14: - | U14: - | V14: 9.126 | W14: - | X14: 13.158 | Y14: - | Z14: - | AA14: - | AB14: - | AC14: -
C15: Z12 | G15: 2.3215046 | H15: 3.1251024 | I15: - | J15: 5.3052334 | K15: 6.3681193 | L15: 9.39 | M15: - | N15: 13.134 | O15: - | P15: 20.706 | Q15: - | R15: 26.118 | S15: - | T15: - | U15: 29.874713 | V15: 39.015232 | W15: 48.653625 | X15: 56.165778 | Y15: - | Z15: 66.116729 | AA15: 77.927366 | AB15: 89.729846 | AC15: -
C16: V12 | G16: 0 | H16: 0.666 | I16: - | J16: 0 | K16: 1.692 | L16: 1.956 | M16: - | N16: 2.748 | O16: - | P16: 4.392 | Q16: - | R16: 5.538 | S16: - | T16: - | U16: 6.666 | V16: 8.694 | W16: 11.184 | X16: 12.906 | Y16: - | Z16: - | AA16: - | AB16: - | AC16: -
C18: COVER | D18: Rope Dia | H18: 4 | I18: 5 | J18: 6 | K18: 7 | L18: 8 | M18: 9 | N18: 10 | O18: 11 | P18: 12 | Q18: 13 | R18: 14 | T18: 15 | U18: 16 | V18: 18 | W18: 20 | X18: 22 | Y18: 23 | Z18: 24 | AA18: 26 | AB18: 28 | AC18: 30
D19: Core Dia | H19: 3mm | I19: 3.5mm | J19: 4 | K19: 5 | L19: 6 | M19: 6.5 | N19: 7 | O19: 8 | P19: 9 | R19: 10 | U19: 11 | V19: 13 | W19: 15 | X19: 16 | Y19: 17 | Z19: 18 | AA19: 19 | AB19: 20
C20: MGP Racing 100 | G20: - | H20: 0.342 | I20: 0.372 | J20: 0.426 | K20: 0.48 | L20: 0.654 | M20: 0.738 | N20: 0.816 | O20: 0.9 | P20: 1.146 | Q20: - | R20: 1.908 | S20: - | T20: - | U20: 2.622 | V20: 3.426 | W20: 3.774 | X20: 4.77 | Y20: 4.7989947 | Z20: 5.184 | AA20: 5.959164 | AB20: 6.640644 | AC20: 7.284264
C21: MGP Technora 50 | G21: - | H21: 0.954 | I21: 0.92670243 | J21: 0.99 | K21: 1.29 | L21: 1.608 | M21: 1.8 | N21: 1.998 | O21: 2.856 | P21: 3.192 | Q21: - | R21: 4.002 | S21: - | T21: - | U21: 5.1 | V21: 6.792 | W21: 7.998 | X21: 10.320636 | Y21: 12.054 | Z21: 14.053632 | AA21: 16.05181 | AB21: 16.8544 | AC21: 19.286994
C22: MGP PBO 100 | G22: - | H22: - | I22: - | J22: 5.226 | K22: 6.258 | L22: 8.382 | M22: 12.552 | N22: 12.552 | O22: 14.634 | P22: 18.804 | Q22: - | R22: 22.992 | S22: - | T22: - | U22: 31.356 | V22: 39.702 | W22: 44.930788 | X22: 57.433057 | Y22: 72.54702 | Z22: 80.406281 | AA22: 90.683775 | AB22: 102.77495 | AC22: 104.58862
C23: MGP P Tech 50 | G23: - | H23: - | I23: - | J23: 3.4971384 | K23: 4.302 | L23: 5.916 | M23: 8.568 | N23: 8.568 | O23: 10.674 | P23: 11.832 | Q23: - | R23: 17.172 | S23: - | T23: - | U23: 20.4 | V23: 25.74 | W23: 31.086 | X23: 39.296582 | Y23: 50.808 | Z23: 55.015214 | AA23: 62.047234 | AB23: 70.320199 | AC23: 72.340726
C24: MGP PBO 50 | G24: - | H24: - | I24: - | J24: 3.336 | K24: 3.8617337 | L24: 4.572 | M24: 6.648 | N24: 6.648 | O24: 8.946 | P24: 11.22 | Q24: - | R24: 13.434 | S24: - | T24: - | U24: 15.972 | V24: 20.878169 | W24: 25.11 | X24: 31.944 | Y24: 36.522 | Z24: 43.286227 | AA24: 48.819053 | AB24: 55.32826 | AC24: 56.451971
C25: MGP D Tech 50 | G25: - | H25: - | I25: - | J25: 1.836 | K25: - | L25: 2.946 | M25: - | N25: 3.684 | O25: - | P25: 5.778 | Q25: - | R25: 7.368 | S25: - | T25: - | U25: 9.576 | V25: 12.408 | W25: 13.901454 | X25: 18.069334 | Y25: - | Z25: 24.922371 | AA25: - | AB25: 29.315134 | AC25: -
C26: MGP M-Grip 50 | G26: - | H26: - | I26: - | J26: - | K26: - | L26: 9.1773 | M26: - | N26: 11.471625 | O26: - | P26: 18.362943 | Q26: - | R26: 22.951593 | S26: - | T26: - | U26: 29.834568 | V26: 39.011868 | W26: 45.903186 | X26: - | Y26: - | Z26: 59.669136 | AA26: - | AB26: 82.295352 | AC26: -
C27: MGP Vectran 50 | G27: - | H27: - | I27: - | J27: 0.972 | K27: 1.1997487 | L27: 1.542 | M27: 1.8 | N27: 1.902 | O27: - | P27: 3.102 | Q27: - | R27: 3.774 | S27: - | T27: - | U27: 5.016 | V27: 6.2559033 | W27: 7.3639747 | X27: 9.5731671 | Y27: - | Z27: 13.200214 | AA27: 15.532195 | AB27: 16.308308 | AC27: 18.658161
C28: MGP Dyneema 50 | G28: - | H28: - | I28: - | J28: 1.224 | K28: 1.464 | L28: 1.812 | M28: - | N28: 2.268 | O28: - | P28: 3.63 | Q28: - | R28: 4.53 | S28: - | T28: - | U28: 5.88 | V28: 7.2611709 | W28: 8.5396615 | X28: - | Y28: - | Z28: - | AA28: - | AB28: - | AC28: -
C29: MGP Runnertail 75 | G29: - | H29: - | I29: - | J29: - | K29: - | L29: 1.614 | M29: - | N29: 2.196 | O29: - | P29: 3.522 | Q29: - | R29: 4.374 | S29: - | T29: - | U29: 5.3844123 | V29: 7.0398937 | W29: 8.2856025 | X29: 10.768825 | Y29: - | Z29: 14.858355 | AA29: - | AB29: 18.349618 | AC29: -
C31: EXTRAS | D31: Rope Dia | F31: 2.5 | G31: 3 | H31: 4 | I31: 5 | J31: 6 | K31: 7 | L31: 8 | M31: 9 | N31: 10 | O31: 11 | P31: 12 | Q31: 13 | R31: 13 | S31: 14 | U31: 14 | V31: 15 | W31: 16 | X31: 18 | Y31: 20 | Z31: 22 | AA31: 24 | AB31: 26 | AC31: 28
C32: MGP Furler 50 | G32: - | H32: - | I32: - | J32: 0.966 | K32: 1.026 | L32: 1.17 | M32: 1.548 | N32: 1.944 | O32: 2.532 | P32: - | Q32: - | R32: - | S32: - | T32: - | U32: - | V32: - | W32: - | X32: - | Y32: - | Z32: - | AA32: - | AB32: - | AC32: -
C33: LashLine | F33: 0.768 | G33: 1.224 | H33: 1.542 | I33: 2.28 | J33: 3.288 | K33: 4.764 | L33: 5.856 | M33: - | N33: 9.54 | O33: - | P33: - | Q33: - | R33: - | S33: - | T33: - | U33: - | V33: - | W33: - | X33: - | Y33: - | Z33: - | AA33: - | AB33: - | AC33: -
C34: Dyneema Chafe Sheave | G34: - | H34: - | I34: 0.744 | J34: - | K34: - | L34: 1.488 | M34: - | N34: 2.232 | O34: - | P34: 3.342 | Q34: - | R34: - | S34: 4.452 | T34: - | U34: 4.452 | V34: - | W34: 5.556 | X34: - | Y34: 8.382 | Z34: - | AA34: 10.062 | AB34: - | AC34: -
C35: Black Dyneema Chafe Sheave | G35: - | H35: - | I35: 0.77600082 | J35: - | K35: - | L35: 1.5435669 | M35: - | N35: 2.3195677 | O35: - | P35: 3.4751341 | Q35: - | R35: - | S35: 4.6222658 | T35: - | U35: 4.6222658 | V35: - | W35: 5.7778322 | X35: - | Y35: 8.7131397 | Z35: - | AA35: 10.459142 | AB35: - | AC35: -
C36: Technora Chafe Sheave | G36: - | H36: - | I36: - | J36: - | K36: - | L36: 2.484 | M36: - | N36: 3.102 | O36: - | P36: 5.154 | Q36: - | R36: - | S36: 6.192 | T36: - | U36: 6.192 | V36: - | W36: 8.244 | X36: - | Y36: - | Z36: - | AA36: - | AB36: - | AC36: -
C37: Pro-Drive | G37: - | H37: - | I37: - | J37: - | K37: 2.112 | L37: - | M37: 3.48 | N37: - | O37: 5.01 | P37: - | Q37: 6.318 | R37: 6.318 | S37: - | T37: - | U37: - | V37: 10.296 | W37: - | X37: - | Y37: - | Z37: - | AA37: - | AB37: - | AC37: -
C38: Colligo Torsion rope clamp | G38: - | H38: - | I38: - | J38: - | K38: 30.126483 | L38: - | M38: 30.126483 | N38: - | O38: 30.126483 | P38: - | Q38: 33.199778 | R38: 33.199778 | S38: - | T38: - | U38: - | V38: 33.199778 | W38: - | X38: - | Y38: - | Z38: - | AA38: - | AB38: - | AC38: -
C40: FINISHES | D40: Rope Dia | F40: 2.5 | G40: 3 | H40: 4 | I40: 5 | J40: 6 | K40: 7 | L40: 8 | M40: 9 | N40: 10 | O40: 11 | P40: 12 | Q40: 13 | R40: 14 | T40: 15 | U40: 16 | V40: 18 | W40: 20 | X40: 22 | Y40: 23 | Z40: 24 | AA40: 26 | AB40: 28 | AC40: 30
D41: Core Dia | G41: 2.5mm | H41: 3mm | I41: 4mm | J41: 5mm | K41: 6mm | M41: 7mm | O41: 9mm | P41: 10mm | R41: 11mm | U41: 13mm | V41: 16mm | W41: 18mm | X41: 20mm | Z41: 22mm
C42: DriCoat | D42: per m | G42: - | H42: - | I42: 0.20455849 | J42: 0.24717485 | K42: 0.27044993 | L42: 0.3 | M42: 0.39338172 | N42: 0.504 | O42: 0.6392453 | P42: 1.002 | Q42: - | R42: 1.296 | S42: - | T42: - | U42: 1.692 | V42: 2.004 | W42: 2.4 | X42: 2.4665925 | Y42: 2.5487857 | Z42: 2.7530164
C43: GripCoat | D43: per m | G43: - | H43: - | I43: 0.20455849 | J43: 0.24717485 | K43: 0.27044993 | L43: 0.30525912 | M43: 0.39338172 | N43: 0.50608749 | O43: 0.6392453 | P43: 1.012175 | Q43: - | R43: 1.309401 | S43: - | T43: - | U43: 1.7110577 | V43: 2.02435 | W43: 2.4260067 | X43: 2.4665925 | Y43: 2.5487857 | Z43: 2.7530164
C45: SHORT LENGTH SURCHARGE
C46: Surchage (Less than 50m) | G46: 0.2 | H46: 0.2 | I46: 0.2 | J46: 0.2 | K46: 0.2 | L46: 0.2 | M46: 0.2 | N46: 0.2 | O46: 0.2 | P46: 0.2 | Q46: 0.2 | R46: 0.2 | S46: -1.8 | T46: 0.2 | U46: 0.2 | V46: 0.2 | W46: 0.2 | X46: 0.2 | Y46: 0.2 | Z46: 0.2 | AA46: 0.2 | AB46: 0.2 | AC46: 0.2
C48: CUSTOMISATIONS | F48: Rope Dia | J48: 6 | K48: 7 | L48: 8 | M48: 9 | N48: 10 | O48: 11 | P48: 12 | Q48: 13 | R48: 14 | T48: 15 | U48: 16 | V48: 18 | W48: 20 | X48: 22 | Y48: 23 | Z48: 24 | AA48: 26 | AB48: 28 | AC48: 30
...

Sheet Hoja1
E3: 30 | F3: Retail
C4: 7mm | D4: =+'Price List'!N9 -> 3.126 | E4: =+D4*E3 -> 93.78 | F4: 4.41 | G4: =+F4*E3 -> 132.3
C5: 10mm | D5: 2 | E5: =+D5*E3 -> 60 | F5: 5 | G5: =+F5*E3 -> 150
D6: cost | E6: =+E5+E4 -> 153.78 | G6: =+G5+G4 -> 282.3
C9: cabo | D9: 282
C10: tylaska | D10: 200
C11: splice | D11: 20

Sheet Order
C11: Marlow Grand Prix Series | E11: ='Price List'!V2 -> EUR
C13: Overall Rope Diameter (mm) | E13: 10
B14: Cores | C14: Core Diameter (mm) | D14: Core Diameter | E14: 7
C15: Core Type | D15: 1 | E15: =IFERROR(CHOOSE($D$15,C16,C17,C18,C19,C20,C21,C22),"") -> D12 78
C16: ='Price List'!C9 -> D12 78 | D16: 1 | E16: =IFERROR(INDEX('Price List'!C8:AC16,MATCH(Order!E15,'Price List'!C8:C16,0),MATCH(Order!E14,'Price List'!C8:AC8,0)),"Not Available") -> 3.126
C17: ='Price List'!C10 -> D12 99 | D17: 2
C18: ='Price List'!C11 -> D12 Max 78 | D18: 3
C19: ='Price List'!C12 -> D12 Max 99 | D19: 4
C20: ='Price List'!C13 -> M-Rig Max | D20: 5
C21: ='Price List'!C15 -> Z12 | D21: 6
C22: ='Price List'!C16 -> V12 | D22: 7
B23: Covers | C23: Cover Type | D23: 2 | E23: =IFERROR(CHOOSE($D$23,C24,C25,C26,C27,C28,C29,C30,C31,C32,C33),"") -> MGP Technora 50
C24: ='Price List'!C20 -> MGP Racing 100 | D24: 1 | E24: =IFERROR(INDEX('Price List'!C18:AC29,MATCH(E23,'Price List'!C18:C29,0),MATCH(Order!E13,'Price List'!C18:AC18,0)),"Not Available") -> 1.998
C25: ='Price List'!C21 -> MGP Technora 50 | D25: 2
C26: ='Price List'!C23 -> MGP P Tech 50 | D26: 3
C27: ='Price List'!C22 -> MGP PBO 100 | D27: 4
C28: ='Price List'!C27 -> MGP Vectran 50 | D28: 5
C29: ='Price List'!C26 -> MGP M-Grip 50 | D29: 6
C30: ='Price List'!C24 -> MGP PBO 50 | D30: 7
C31: ='Price List'!C28 -> MGP Dyneema 50 | D31: 8
C32: ='Price List'!C25 -> MGP D Tech 50 | D32: 9
C33: ='Price List'!C29 -> MGP Runnertail 75 | D33: 10
C35: Rope Price (per m) | E35: =IFERROR(E24+E16,"-") -> 5.124
C36: Length Required (meters) | E36: 20
C37: Short Length Surchage (<50m) | D37: 0.2 | E37: =IFERROR(IF(E36<50,E35*D37,"0"),"-") -> 1.0248 | H37: 6.15 | I37: metro | K37: 27 | L37: =+H37*K37 -> 166.05
C38: Rope Price (per m) inc. surcharge | E38: =IF(ISERROR(E37+E35)," ",(E37+E35)) -> 6.1488 | H38: 12.81 | I38: retail | K38: 27 | L38: =+H38*K38 -> 345.87 | M38: =+L38/2 -> 172.935
B40: Total Rope Price (inc. Short Length Surcharge | D40: =E11 -> EUR | E40: =IFERROR(E38*E36,"-") -> 122.976
H41: 5.12 | K41: 50 | L41: =+H41*K41 -> 256
K42: 27 | L42: =+H42*K42 -> 0

Sheet Product List
A5: PartNumber | B5: Description | E5: Customer price
A6: JTY414 | B6: EXCEL D12 78 2.5mm S/YELLOW | C6: 2.5 | E6: 0.588
A7: JTY415 | B7: EXCEL D12 78 2.5mm S/RED | C7: 2.5 | E7: 0.588
A8: JTY419 | B8: EXCEL D12 78 2.5mm S/BLACK | C8: 2.5 | E8: 0.588
A9: JTY429 | B9: EXCEL D12 78 2.5mm S/BLUE | C9: 2.5 | E9: 0.588
A10: JTY431 | B10: EXCEL D12 78 2.5mm S/LIME | C10: 2.5 | E10: 0.588
A11: JTY430 | B11: EXCEL D12 78 2.5mm S/GREEN | C11: 2.5 | E11: 0.588
A12: JTY415 | B12: EXCEL D12 78 2.5mm S/RED | C12: 2.5 | E12: 0.588
A13: JTY428 | B13: EXCEL D12 78 2.5mm WHITE | C13: 2.5 | E13: 0.588
A14: JTY418 | B14: EXCEL D12 78 3mm S/BLACK | C14: 3 | E14: 0.942
A15: JTY432 | B15: EXCEL D12 78 3mm S/BLUE | C15: 3 | E15: 0.942
A16: JTY433 | B16: EXCEL D12 78 3mm S/GREEN | C16: 3 | E16: 0.942
A17: JTY434 | B17: EXCEL D12 78 3mm S/YELLOW | C17: 3 | E17: 0.942
... A20: JTY446 | B20: EXCEL D12 78 3mm S/ORANGE | C20: 3 | E20: 0.942
A21: JTY449 | B21: EXCEL D12 78 3mm S/PINK | C21: 3 | E21: 0.942
A22: JTY411 | B22: EXCEL D12 78 3mm WHITE | C22: 3 | E22: 0.942
A23: JTY416 | B23: EXCEL D12 78 3mm S/RED | C23: 3 | E23: 0.942
A24: JTY418 | B24: EXCEL D12 78 3mm S/BLACK | C24: 3 | E24: 0.942
A25: JTY412 | B25: EXCEL D12 78 3.5mm WHITE | C25: 3.5 | E25: 1.092
A26: JTY423 | B26: EXCEL D12 78 3.5mm S/BLACK | C26: 3.5 | E26: 1.092
A27: JTY437 | B27: EXCEL D12 78 3.5mm S/BLUE | C27: 3.5 | E27: 1.092
A28: JTY438 | B28: EXCEL D12 78 3.5mm S/GREEN | C28: 3.5 | E28: 1.092
A29: JTY439 | B29: EXCEL D12 78 3.5mm S/YELLOW | C29: 3.5 | E29: 1.092
A30: JTY440 | B30: EXCEL D12 78 3.5mm S/LIME | C30: 3.5 | E30: 1.092
A31: JTY410 | B31: EXCEL D12 78 4mm S/BLACK | C31: 4 | E31: 1.194
A32: JTY413 | B32: EXCEL D12 78 4mm WHITE | C32: 4 | E32: 1.194
A33: JTY427 | B33: EXCEL D12 78 4mm S/GREEN | C33: 4 | E33: 1.194
... A87: KBD488 | B87: D12 SK78 17mm BLACK | C87: 17 | E87: 14.382
B88: Error (523): Invalid Stock Code | C88: 18 | E88: 14.794931
B89: Error (523): Invalid Stock Code | C89: 19 | E89: 17.695764
B90: Error (523): Invalid Stock Code | C90: 20 | E90: 20.224812
C91: 22 | E91: 23.405052
A92: JTY510 | B92: EXCEL D12 90 3mm S/BLACK | C92: 3 | E92: 1.224
A93: JTY511 | B93: EXCEL D12 90 3mm WHITE | C93: 3 | E93: 1.224
A94: JTY523 | B94: EXCEL D12 90 4mm WHITE | C94: 4 | E94: 1.542
A95: JTY532 | B95: EXCEL D12 90 5mm S/BLACK | C95: 5 | E95: 2.28
A96: KBD550 | B96: D12 SK90 6mm (H for 8mm) WHITE | C96: 6 | E96: 3.288
A97: KBD551 | B97: D12 SK90 6mm (H for 8mm) RED | C97: 6 | E97: 3.288
A98: KBD552 | B98: D12 SK90 6mm (H for 8mm) BLUE | C98: 6 | E98: 3.288
A99: KBD553 | B99: D12 SK90 6mm (H for 8mm) GREEN | C99: 6 | E99: 3.288
...

Sheet retail
D18: core | E18: length | F18: COST | G18: RETAIL | I18: cover | J18: length | K18: COST | L18: RETAIL | O18: TOT
D19: 8 | E19: 19 | F19: 54.63 | G19: =8.63*E19 -> 163.97 | I19: 8 | J19: 15 | K19: 22.32 | L19: =3.72*J19 -> 55.8 | N19: =+F19+K19 -> 76.95 | O19: =+L19+G19 -> 219.77
D21: 18 | E21: 15 | F21: 290 | G21: =36.99*E21 -> 554.85 | I21: 14 | J21: 15 | K21: 80.14 | L21: =11.13*J21 -> 166.95 | N21: =+F21+K21 -> 370.14 | O21: =+L21+G21 -> 721.8
N22: 50
N24: =+SUM(N19:N22) -> 497.09 | O24: =+SUM(O19:O22) -> 941.57 | P24: =+O24*0.8 -> 753.256
