Workbook

Sheet Pro Race
B11: PRICE LIST
B12: ref. 01-2017
B14: prices are ex-taxes and can be changed without prior notice
B15: position EXW Factory Portugal
B16: alpha ropes®
B17: valid from January 1st, 2017
B24: PRO RACE | G24: Suggested Retail Price
B26: Product | C26: Colour | D26: Diam. | E26: Mts | G26: Retail €/mt | H26: Retail €/100mt
B27: D-Core 99
B28: D-Core 99 | C28: solid | D28: 2.5 | E28: 200 | F28: Spool | G28: =(H28/100) -> 1.3028175 | H28: 130.28175
B29: D-Core 99 | C29: solid | D29: 3 | E29: 200 | F29: Spool | G29: =(H29/100) -> 2.0346563 | H29: 203.46563
B30: D-Core 99 | C30: solid | D30: 4 | E30: 200 | F30: Spool | G30: =(H30/100) -> 2.8756901 | H30: 287.56901
B31: D-Core 99 | C31: solid | D31: 5 | E31: 200 | F31: Spool | G31: =(H31/100) -> 5.523 | H31: 552.3
B32: D-Core 99 | C32: solid | D32: 6 | E32: 200 | F32: Spool | G32: =(H32/100) -> 7.51245 | H32: 751.245
B33: D-Core 99 | C33: solid | D33: 7 | E33: 200 | F33: Spool | G33: =(H33/100) -> 9.5613 | H33: 956.13
B34: D-Core 99 | C34: solid | D34: 8 | E34: 200 | F34: Spool | G34: =(H34/100) -> 13.269262 | H34: 1326.9262
B35: D-Core 99 | C35: solid | D35: 9 | E35: 200 | F35: Spool | G35: =(H35/100) -> 18.032587 | H35: 1803.2587
B36: D-Core 99 | C36: solid | D36: 10 | E36: 200 | F36: Spool | G36: =(H36/100) -> 20.754488 | H36: 2075.4488
B37: D-Core 99 | C37: solid | D37: 12 | E37: 200 | F37: Spool | G37: =(H37/100) -> 23.668696 | H37: 2366.8696
B38: D-Core 99 | C38: solid | D38: 14 | E38: 100 | F38: Spool | G38: =(H38/100) -> 26.627838 | H38: 2662.7838
B39: D-Core 99 | C39: solid | D39: 16 | E39: 100 | F39: Spool | G39: =(H39/100) -> 35.503784 | H39: 3550.3784
... B44: D-Core 99 | C44: solid | D44: 26 | E44: 100 | F44: Spool | G44: =(H44/100) -> 97.93127 | H44: 9793.127
B46: D-Cup 99
B47: D-Cup 99 | C47: mix grey + colour | D47: 4 | E47: 200 | F47: Spool | G47: =(H47/100) -> 2.7976576 | H47: 279.76576
B48: D-Cup 99 | C48: mix grey + colour | D48: 5 | E48: 200 | F48: Spool | G48: =(H48/100) -> 3.5867492 | H48: 358.67492
B49: D-Cup 99 | C49: mix grey + colour | D49: 6 | E49: 200 | F49: Spool | G49: =(H49/100) -> 3.8601031 | H49: 386.01031
B50: D-Cup 99 | C50: mix grey + colour | D50: 7 | E50: 200 | F50: Spool | G50: =(H50/100) -> 4.7030797 | H50: 470.30797
B51: D-Cup 99 | C51: mix grey + colour | D51: 8 | E51: 200 | F51: Spool | G51: =(H51/100) -> 7.7692068 | H51: 776.92068
B52: D-Cup 99 | C52: mix grey + colour | D52: 9 | E52: 200 | F52: Spool | G52: =(H52/100) -> 9.2903644 | H52: 929.03644
B53: D-Cup 99 | C53: mix grey + colour | D53: 10 | E53: 200 | F53: Spool | G53: =(H53/100) -> 10.389478 | H53: 1038.9478
B54: D-Cup 99 | C54: mix grey + colour | D54: 11 | E54: 200 | F54: Spool | G54: =(H54/100) -> 13.669108 | H54: 1366.9108
B55: D-Cup 99 | C55: mix grey + colour | D55: 12 | E55: 200 | F55: Spool | G55: =(H55/100) -> 15.152239 | H55: 1515.2239
B56: D-Cup 99 | C56: mix grey + colour | D56: 14 | E56: 100 | F56: Spool | G56: =(H56/100) -> 21.320876 | H56: 2132.0876
B57: D-Cup 99 | C57: mix grey + colour | D57: 16 | E57: 100 | F57: Spool | G57: =(H57/100) -> 25.843487 | H57: 2584.3487
B58: D-Cup 99 | C58: mix grey + colour | D58: 18 | E58: 100 | F58: Spool | G58: =(H58/100) -> 33.717313 | H58: 3371.7313
B59: D-Cup 99 | C59: mix grey + colour | D59: 20 | E59: 100 | F59: Spool | G59: =(H59/100) -> 40.460776 | H59: 4046.0776
B61: D-Cup 99 Kmix
B62: D-Cup 99 Kmix | C62: mix grey + colour | D62: 5 | E62: 200 | F62: Spool | G62: =(H62/100) -> 3.7514648 | H62: 375.14648
B63: D-Cup 99 Kmix | C63: mix grey + colour | D63: 6 | E63: 200 | F63: Spool | G63: =(H63/100) -> 4.2442916 | H63: 424.42916
B64: D-Cup 99 Kmix | C64: mix grey + colour | D64: 7 | E64: 200 | F64: Spool | G64: =(H64/100) -> 4.9469946 | H64: 494.69946
...

Sheet Skincovers
B10: PRICE LIST
B11: ='Pro Race'!B12 -> ref. 01-2017
B13: prices are ex-taxes and can be changed without prior notice
B14: position EXW Factory Portugal
B15: alpha ropes®
B16: ='Pro Race'!B17 -> valid from January 1st, 2017
B24: SKINCOVERS | G24: Suggested Retail Price
B26: Product | C26: Colour | D26: Diam. | E26: Mts | G26: Retail €/mt | H26: Retail €/100mt
B27: SkinCover PES
B28: SkinCover PES | C28: mix grey + colour | D28: 4 to 7 | E28: 100 | F28: Spool | G28: =(H28/100) -> 0.59267368 | H28: 59.267368
B29: SkinCover PES | C29: mix grey + colour | D29: 8 to 11 | E29: 100 | F29: Spool | G29: =(H29/100) -> 0.75410526 | H29: 75.410526
B30: SkinCover PES | C30: mix grey + colour | D30: 12 to 14 | E30: 100 | F30: Spool | G30: =(H30/100) -> 1.1067158 | H30: 110.67158
B31: SkinCover PES | C31: mix grey + colour | D31: 16 to 18 | E31: 100 | F31: Spool | G31: =(H31/100) -> 1.7260295 | H31: 172.60295
B32: SkinCover PES | C32: mix grey + colour | D32: core 25mm | E32: 100 | F32: Spool | G32: =(H32/100) -> 3.1872 | H32: 318.72
B33: SkinCover PES | C33: mix grey + colour | D33: core 30mm | E33: 100 | F33: Spool | G33: =(H33/100) -> 4.5291789 | H33: 452.91789
B34: SkinCover PES | C34: mix grey + colour | D34: core 35mm | E34: 100 | F34: Spool | G34: =(H34/100) -> 5.3679158 | H34: 536.79158
B36: SkinCover KMIX
B37: SkinCover KMIX | C37: mix grey + colour | D37: 4 to 7 | E37: 100 | F37: Spool | G37: =(H37/100) -> 0.96559158 | H37: 96.559158
B38: SkinCover KMIX | C38: mix grey + colour | D38: 8 to 11 | E38: 100 | F38: Spool | G38: =(H38/100) -> 1.4895158 | H38: 148.95158
B39: SkinCover KMIX | C39: mix grey + colour | D39: 12 to 14 | E39: 100 | F39: Spool | G39: =(H39/100) -> 3.5580632 | H39: 355.80632
B41: SkinCover KMIX Special
B42: SkinCover KMIX Special | C42: mix white + colour | D42: 4 to 7 | E42: 100 | F42: Spool | G42: =(H42/100) -> 1.7992758 | H42: 179.92758
B43: SkinCover KMIX Special | C43: mix white + colour | D43: 8 to 11 | E43: 100 | F43: Spool | G43: =(H43/100) -> 4.5116211 | H43: 451.16211
B44: SkinCover KMIX Special | C44: mix white + colour | D44: 12 to 14 | E44: 100 | F44: Spool | G44: =(H44/100) -> 8.0155453 | H44: 801.55453
B46: SkinCover Kmix KV
B47: SkinCover Kmix KV | C47: mix kevlar + colour | D47: 4 to 7 | E47: 100 | F47: Spool | G47: =(H47/100) -> 1.8416842 | H47: 184.16842
B48: SkinCover Kmix KV | C48: mix kevlar + colour | D48: 8 to 11 | E48: 100 | F48: Spool | G48: =(H48/100) -> 3.1815789 | H48: 318.15789
B49: SkinCover Kmix KV | C49: mix kevlar + colour | D49: 12 to 14 | E49: 100 | F49: Spool | G49: =(H49/100) -> 5.0289474 | H49: 502.89474
B50: SkinCover Kmix KV | C50: mix kevlar + colour | D50: 16 to 18 | E50: 100 | F50: Spool | G50: =(H50/100) -> 8.9810526 | H50: 898.10526
B52: SkinCover Kmix TN
B53: SkinCover Kmix TN | C53: mix black technora + colour | D53: 4 to 7 | E53: 100 | F53: Spool | G53: =(H53/100) -> 2.1401053 | H53: 214.01053
B54: SkinCover Kmix TN | C54: mix black technora + colour | D54: 8 to 11 | E54: 100 | F54: Spool | G54: =(H54/100) -> 3.7526316 | H54: 375.26316
B55: SkinCover Kmix TN | C55: mix black technora + colour | D55: 12 to 14 | E55: 100 | F55: Spool | G55: =(H55/100) -> 5.9315789 | H55: 593.15789
B56: SkinCover Kmix TN | C56: mix black technora + colour | D56: 16 to 18 | E56: 100 | F56: Spool | G56: =(H56/100) -> 10.727368 | H56: 1072.7368
B58: SkinCover Kmix TN MAXI 70%
B59: SkinCover Kmix TN MAXI | C59: mix black technora + colour | D59: 8 to 11 | E59: 100 | F59: Spool | G59: =(H59/100) -> 4.9919158 | H59: 499.19158
B60: SkinCover Kmix TN MAXI | C60: mix black technora + colour | D60: 12 to 15 | E60: 100 | F60: Spool | G60: =(H60/100) -> 9.495 | H60: 949.5
B62: SkinCover Kmix VT
B63: SkinCover Kmix VT | C63: mix vectran beige + colour | D63: 4 to 7 | E63: 100 | F63: Spool | G63: =(H63/100) -> 1.7990526 | H63: 179.90526
B64: SkinCover Kmix VT | C64: mix vectran beige + colour | D64: 8 to 11 | E64: 100 | F64: Spool | G64: =(H64/100) -> 3.1 | H64: 310
...

Sheet Regatta
B10: ='Pro Race'!B11 -> PRICE LIST
B11: ='Pro Race'!B12 -> ref. 01-2017
B13: ='Pro Race'!B14 -> prices are ex-taxes and can be changed without prior notice
B14: ='Pro Race'!B15 -> position EXW Factory Portugal
B15: ='Pro Race'!B16 -> alpha ropes®
B16: ='Pro Race'!B17 -> valid from January 1st, 2017
B24: REGATTA | G24: Suggested Retail Price
B26: Product | C26: Colour | D26: Diam. | E26: Mts | G26: ='Pro Race'!G26 -> Retail €/mt | H26: ='Pro Race'!H26 -> Retail €/100mt
B27: D-Core 78
B28: D-Core 78 | C28: solid | D28: 2.5 | E28: 200 | F28: Spool | G28: =(H28/100) -> 0.8303175 | H28: 83.03175
B29: D-Core 78 | C29: solid | D29: 3 | E29: 200 | F29: Spool | G29: =(H29/100) -> 1.3127813 | H29: 131.27813
B30: D-Core 78 | C30: solid | D30: 4 | E30: 200 | F30: Spool | G30: =(H30/100) -> 1.8109014 | H30: 181.09014
B31: D-Core 78 | C31: solid | D31: 5 | E31: 200 | F31: Spool | G31: =(H31/100) -> 3.423 | H31: 342.3
B32: D-Core 78 | C32: solid | D32: 6 | E32: 200 | F32: Spool | G32: =(H32/100) -> 4.62495 | H32: 462.495
B33: D-Core 78 | C33: solid | D33: 7 | E33: 200 | F33: Spool | G33: =(H33/100) -> 5.8863 | H33: 588.63
B34: D-Core 78 | C34: solid | D34: 8 | E34: 200 | F34: Spool | G34: =(H34/100) -> 8.1505125 | H34: 815.05125
B35: D-Core 78 | C35: solid | D35: 9 | E35: 200 | F35: Spool | G35: =(H35/100) -> 11.076337 | H35: 1107.6337
B36: D-Core 78 | C36: solid | D36: 10 | E36: 200 | F36: Spool | G36: =(H36/100) -> 12.748238 | H36: 1274.8238
B37: D-Core 78 | C37: solid | D37: 12 | E37: 200 | F37: Spool | G37: =(H37/100) -> 14.538261 | H37: 1453.8261
B38: D-Core 78 | C38: solid | D38: 14 | E38: 100 | F38: Spool | G38: =(H38/100) -> 16.411622 | H38: 1641.1622
B39: D-Core 78 | C39: solid | D39: 16 | E39: 100 | F39: Spool | G39: =(H39/100) -> 21.882162 | H39: 2188.2162
... B43: D-Core 78 | C43: solid | D43: 24 | E43: 100 | F43: Spool | G43: =(H43/100) -> 42.305514 | H43: 4230.5514
B45: V-Core
B46: V-Core | C46: solid natural | D46: 3 | E46: 200 | F46: Spool | G46: =(H46/100) -> 1.4525902 | H46: 145.25902
B47: V-Core | C47: solid natural | D47: 4 | E47: 200 | F47: Spool | G47: =(H47/100) -> 1.723025 | H47: 172.3025
B48: V-Core | C48: solid natural | D48: 5 | E48: 200 | F48: Spool | G48: =(H48/100) -> 3.262875 | H48: 326.2875
B49: V-Core | C49: solid natural | D49: 6 | E49: 200 | F49: Spool | G49: =(H49/100) -> 4.338 | H49: 433.8
B50: V-Core | C50: solid natural | D50: 7 | E50: 200 | F50: Spool | G50: =(H50/100) -> 5.6394 | H50: 563.94
B51: V-Core | C51: solid natural | D51: 8 | E51: 200 | F51: Spool | G51: =(H51/100) -> 7.741575 | H51: 774.1575
B52: V-Core | C52: solid natural | D52: 9 | E52: 200 | F52: Spool | G52: =(H52/100) -> 10.809533 | H52: 1080.9533
B53: V-Core | C53: solid natural | D53: 10 | E53: 200 | F53: Spool | G53: =(H53/100) -> 12.6159 | H53: 1261.59
B54: V-Core | C54: solid natural | D54: 12 | E54: 200 | F54: Spool | G54: =(H54/100) -> 15.339788 | H54: 1533.9788
B55: V-Core | C55: solid natural | D55: 14 | E55: 100 | F55: Spool | G55: =(H55/100) -> 18.007125 | H55: 1800.7125
B56: V-Core | C56: solid natural | D56: 16 | E56: 100 | F56: Spool | G56: =(H56/100) -> 24.832406 | H56: 2483.2406
B58: V-Cup
B59: V-Cup | C59: solid | D59: 8 | E59: 200 | F59: Spool | G59: =(H59/100) -> 4.1154864 | H59: 411.54864
B60: V-Cup | C60: solid | D60: 10 | E60: 200 | F60: Spool | G60: =(H60/100) -> 6.6052831 | H60: 660.52831
B61: V-Cup | C61: solid | D61: 12 | E61: 200 | F61: Spool | G61: =(H61/100) -> 9.530625 | H61: 953.0625
B62: V-Cup | C62: solid | D62: 14 | E62: 100 | F62: Spool | G62: =(H62/100) -> 14.168391 | H62: 1416.8391
B63: V-Cup | C63: solid | D63: 16 | E63: 100 | F63: Spool | G63: =(H63/100) -> 19.011544 | H63: 1901.1544
...

Sheet Classic
B10: ='Pro Race'!B11 -> PRICE LIST
B11: ='Pro Race'!B12 -> ref. 01-2017
B13: ='Pro Race'!B14 -> prices are ex-taxes and can be changed without prior notice
B14: ='Pro Race'!B15 -> position EXW Factory Portugal
B15: ='Pro Race'!B16 -> alpha ropes®
B16: ='Pro Race'!B17 -> valid from January 1st, 2017
B24: CLASSIC | G24: Suggested Retail Price
B26: Product | C26: Colour | D26: Diam. | E26: Mts | G26: Retail €/mt | H26: Retail €/100mt
B27: D-Core 78
B28: D-Core 78 | C28: white | D28: 6 | E28: 200 | F28: Spool | G28: =(H28/100) -> 4.62495 | H28: 462.495
B29: D-Core 78 | C29: white | D29: 7 | E29: 200 | F29: Spool | G29: =(H29/100) -> 5.8863 | H29: 588.63
B30: D-Core 78 | C30: white | D30: 8 | E30: 200 | F30: Spool | G30: =(H30/100) -> 8.1505125 | H30: 815.05125
B31: D-Core 78 | C31: white | D31: 9 | E31: 200 | F31: Spool | G31: =(H31/100) -> 11.076337 | H31: 1107.6337
B32: D-Core 78 | C32: white | D32: 10 | E32: 200 | F32: Spool | G32: =(H32/100) -> 12.748238 | H32: 1274.8238
B33: D-Core 78 | C33: white | D33: 12 | E33: 200 | F33: Spool | G33: =(H33/100) -> 14.538261 | H33: 1453.8261
B34: D-Core 78 | C34: white | D34: 14 | E34: 100 | F34: Spool | G34: =(H34/100) -> 16.411622 | H34: 1641.1622
B35: D-Core 78 | C35: white | D35: 16 | E35: 100 | F35: Spool | G35: =(H35/100) -> 21.882162 | H35: 2188.2162
B36: D-Core 78 | C36: white | D36: 18 | E36: 100 | F36: Spool | G36: =(H36/100) -> 27.535054 | H36: 2753.5054
B37: D-Core 78 | C37: white | D37: 20 | E37: 100 | F37: Spool | G37: =(H37/100) -> 30.99973 | H37: 3099.973
B38: D-Core 78 | C38: white | D38: 22 | E38: 100 | F38: Spool | G38: =(H38/100) -> 34.646757 | H38: 3464.6757
B39: D-Core 78 | C39: white | D39: 24 | E39: 100 | F39: Spool | G39: =(H39/100) -> 42.305514 | H39: 4230.5514
B41: V-Core
B42: V-Core | C42: vectran beige | D42: 6 | E42: 200 | F42: Spool | G42: =(H42/100) -> 4.338 | H42: 433.8
B43: V-Core | C43: vectran beige | D43: 7 | E43: 200 | F43: Spool | G43: =(H43/100) -> 5.6394 | H43: 563.94
B44: V-Core | C44: vectran beige | D44: 8 | E44: 200 | F44: Spool | G44: =(H44/100) -> 7.741575 | H44: 774.1575
B45: V-Core | C45: vectran beige | D45: 9 | E45: 200 | F45: Spool | G45: =(H45/100) -> 10.809533 | H45: 1080.9533
B46: V-Core | C46: vectran beige | D46: 10 | E46: 200 | F46: Spool | G46: =(H46/100) -> 12.6159 | H46: 1261.59
B47: V-Core | C47: vectran beige | D47: 12 | E47: 200 | F47: Spool | G47: =(H47/100) -> 15.339788 | H47: 1533.9788
B48: V-Core | C48: vectran beige | D48: 14 | E48: 100 | F48: Spool | G48: =(H48/100) -> 18.007125 | H48: 1800.7125
B49: V-Core | C49: vectran beige | D49: 16 | E49: 100 | F49: Spool | G49: =(H49/100) -> 24.832406 | H49: 2483.2406
B51: D-Cup 78 Classic
B52: D-Cup 78 Classic | C52: solid beige | D52: 6 | E52: 200 | F52: Spool | G52: =(H52/100) -> 2.5992488 | H52: 259.92488
B53: D-Cup 78 Classic | C53: solid beige | D53: 7 | E53: 200 | F53: Spool | G53: =(H53/100) -> 3.1206051 | H53: 312.06051
B54: D-Cup 78 Classic | C54: solid beige | D54: 8 | E54: 200 | F54: Spool | G54: =(H54/100) -> 5.1452746 | H54: 514.52746
B55: D-Cup 78 Classic | C55: solid beige | D55: 9 | E55: 200 | F55: Spool | G55: =(H55/100) -> 6.0762966 | H55: 607.62966
B56: D-Cup 78 Classic | C56: solid beige | D56: 10 | E56: 200 | F56: Spool | G56: =(H56/100) -> 6.8358508 | H56: 683.58508
B57: D-Cup 78 Classic | C57: solid beige | D57: 11 | E57: 200 | F57: Spool | G57: =(H57/100) -> 8.9061726 | H57: 890.61726
B58: D-Cup 78 Classic | C58: solid beige | D58: 12 | E58: 200 | F58: Spool | G58: =(H58/100) -> 9.7361194 | H58: 973.61194
B59: D-Cup 78 Classic | C59: solid beige | D59: 14 | E59: 100 | F59: Spool | G59: =(H59/100) -> 13.675121 | H59: 1367.5121
B60: D-Cup 78 Classic | C60: solid beige | D60: 16 | E60: 100 | F60: Spool | G60: =(H60/100) -> 16.663164 | H60: 1666.3164
...

Sheet Cruising
B10: ='Pro Race'!B11 -> PRICE LIST
B11: ='Pro Race'!B12 -> ref. 01-2017
B13: ='Pro Race'!B14 -> prices are ex-taxes and can be changed without prior notice
B14: ='Pro Race'!B15 -> position EXW Factory Portugal
B15: ='Pro Race'!B16 -> alpha ropes®
B16: ='Pro Race'!B17 -> valid from January 1st, 2017
B24: CRUISING | G24: Suggested Retail Price
B26: Product | C26: Colour | D26: Diam. | E26: Mts | G26: ='Pro Race'!G26 -> Retail €/mt | H26: ='Pro Race'!H26 -> Retail €/100mt
B27: Cruiser 16
B28: Cruiser 16 | C28: white + fleck | D28: 6 | E28: 200 | F28: Spool | G28: =(H28/100) -> 0.7091822 | H28: 70.91822
B29: Cruiser 16 | C29: white + fleck | D29: 7 | E29: 200 | F29: Spool | G29: =(H29/100) -> 0.90917177 | H29: 90.917177
B30: Cruiser 16 | C30: white + fleck | D30: 8 | E30: 200 | F30: Spool | G30: =(H30/100) -> 1.0257712 | H30: 102.57712
B31: Cruiser 16 | C31: white + fleck | D31: 9 | E31: 200 | F31: Spool | G31: =(H31/100) -> 1.3051727 | H31: 130.51727
B32: Cruiser 16 | C32: white + fleck | D32: 10 | E32: 200 | F32: Spool | G32: =(H32/100) -> 1.4764 | H32: 147.64
B33: Cruiser 16 | C33: white + fleck | D33: 12 | E33: 200 | F33: Spool | G33: =(H33/100) -> 1.8658111 | H33: 186.58111
B34: Cruiser 16 | C34: white + fleck | D34: 14 | E34: 200 | F34: Spool | G34: =(H34/100) -> 2.3797222 | H34: 237.97222
B35: Cruiser 16 | C35: white + fleck | D35: 16 | E35: 100 | F35: Spool | G35: =(H35/100) -> 3.0936389 | H35: 309.36389
B36: Cruiser 16 | C36: white + fleck | D36: 18 | E36: 100 | F36: Spool | G36: =(H36/100) -> 3.7709444 | H36: 377.09444
B37: Cruiser 16 | C37: white + fleck | D37: 20 | E37: 100 | F37: Spool | G37: =(H37/100) -> 4.8143611 | H37: 481.43611
B39: Cruiser 16 | C39: solid colour | D39: 6 | E39: 200 | F39: Spool | G39: =(H39/100) -> 0.73427542 | H39: 73.427542
B40: Cruiser 16 | C40: solid colour | D40: 7 | E40: 200 | F40: Spool | G40: =(H40/100) -> 0.99343576 | H40: 99.343576
... B48: Cruiser 16 | C48: solid colour | D48: 20 | E48: 100 | F48: Spool | G48: =(H48/100) -> 5.1358056 | H48: 513.58056
B50: Cruiser 24
B51: Cruiser 24 | C51: white + fleck | D51: 5 | E51: 200 | F51: Spool | G51: =(H51/100) -> 0.53800678 | H51: 53.800678
B52: Cruiser 24 | C52: white + fleck | D52: 6 | E52: 200 | F52: Spool | G52: =(H52/100) -> 0.88612881 | H52: 88.612881
B53: Cruiser 24 | C53: white + fleck | D53: 7 | E53: 200 | F53: Spool | G53: =(H53/100) -> 1.006829 | H53: 100.6829
B54: Cruiser 24 | C54: white + fleck | D54: 8 | E54: 200 | F54: Spool | G54: =(H54/100) -> 1.0569153 | H54: 105.69153
B55: Cruiser 24 | C55: white + fleck | D55: 9 | E55: 200 | F55: Spool | G55: =(H55/100) -> 1.3746244 | H55: 137.46244
B56: Cruiser 24 | C56: white + fleck | D56: 10 | E56: 200 | F56: Spool | G56: =(H56/100) -> 1.6858333 | H56: 168.58333
B57: Cruiser 24 | C57: white + fleck | D57: 12 | E57: 200 | F57: Spool | G57: =(H57/100) -> 2.1105778 | H57: 211.05778
B58: Cruiser 24 | C58: white + fleck | D58: 14 | E58: 200 | F58: Spool | G58: =(H58/100) -> 2.6375556 | H58: 263.75556
B59: Cruiser 24 | C59: white + fleck | D59: 16 | E59: 100 | F59: Spool | G59: =(H59/100) -> 3.4491111 | H59: 344.91111
B60: Cruiser 24 | C60: white + fleck | D60: 18 | E60: 100 | F60: Spool | G60: =(H60/100) -> 4.3713333 | H60: 437.13333
B61: Cruiser 24 | C61: white + fleck | D61: 22 | E61: 100 | F61: Spool | G61: =(H61/100) -> 6.1235556 | H61: 612.35556
B63: Cruiser 24 | C63: solid colour | D63: 4 | E63: 200 | F63: Spool | G63: =(H63/100) -> 0.49054909 | H63: 49.054909
... B74: Cruiser 24 | C74: solid colour | D74: 22 | E74: 100 | F74: Spool | G74: =(H74/100) -> 6.4205111 | H74: 642.05111
B76: Cruiser 24 Kmix
B77: Cruiser 24 Kmix | C77: solid colour | D77: 4 | E77: 200 | F77: Spool | G77: =(H77/100) -> 0.62466102 | H77: 62.466102
B78: Cruiser 24 Kmix | C78: solid colour | D78: 6 | E78: 200 | F78: Spool | G78: =(H78/100) -> 1.2453356 | H78: 124.53356
B79: Cruiser 24 Kmix | C79: solid colour | D79: 8 | E79: 200 | F79: Spool | G79: =(H79/100) -> 1.7078263 | H79: 170.78263
...

Sheet Olympic Line
B10: ='Pro Race'!B11 -> PRICE LIST
B11: ='Pro Race'!B12 -> ref. 01-2017
B13: ='Pro Race'!B14 -> prices are ex-taxes and can be changed without prior notice
B14: ='Pro Race'!B15 -> position EXW Factory Portugal
B15: ='Pro Race'!B16 -> alpha ropes®
B16: ='Pro Race'!B17 -> valid from January 1st, 2017
B24: OLYMPIC & ONE DESIGN | G24: Suggested Retail Price
B26: Product | C26: Colour | D26: Diam. | E26: Mts | G26: ='Pro Race'!G26 -> Retail €/mt | H26: ='Pro Race'!H26 -> Retail €/100mt
B27: D-Core 78
B28: D-Core 78 | C28: solid | D28: 2.5 | E28: 200 | F28: Spool | G28: =(H28/100) -> 0.8303175 | H28: 83.03175
B29: D-Core 78 | C29: solid | D29: 3 | E29: 200 | F29: Spool | G29: =(H29/100) -> 1.3127813 | H29: 131.27813
B30: D-Core 78 | C30: solid | D30: 4 | E30: 200 | F30: Spool | G30: =(H30/100) -> 1.8109014 | H30: 181.09014
B31: D-Core 78 | C31: solid | D31: 5 | E31: 200 | F31: Spool | G31: =(H31/100) -> 3.423 | H31: 342.3
B32: D-Core 78 | C32: solid | D32: 6 | E32: 200 | F32: Spool | G32: =(H32/100) -> 4.62495 | H32: 462.495
B33: D-Core 78 | C33: solid | D33: 7 | E33: 200 | F33: Spool | G33: =(H33/100) -> 5.8863 | H33: 588.63
B34: D-Core 78 | C34: solid | D34: 8 | E34: 200 | F34: Spool | G34: =(H34/100) -> 8.1505125 | H34: 815.05125
B36: D-Core 78 XTM
B37: D-Core 78 XTM | C37: solid | D37: 3 | E37: 200 | F37: Spool | G37: =(H37/100) -> 1.4130492 | H37: 141.30492
B38: D-Core 78 XTM | C38: solid | D38: 4 | E38: 200 | F38: Spool | G38: =(H38/100) -> 2.1591176 | H38: 215.91176
B39: D-Core 78 XTM | C39: solid | D39: 5 | E39: 200 | F39: Spool | G39: =(H39/100) -> 4.1571148 | H39: 415.71148
B40: D-Core 78 XTM | C40: solid | D40: 6 | E40: 200 | F40: Spool | G40: =(H40/100) -> 5.4493377 | H40: 544.93377
B42: D-Power 78
B43: D-Power 78 | C43: solid | D43: 3 | E43: 200 | F43: Spool | G43: =(H43/100) -> 1.1934375 | H43: 119.34375
B44: D-Power 78 | C44: solid | D44: 4 | E44: 200 | F44: Spool | G44: =(H44/100) -> 1.78575 | H44: 178.575
B45: D-Power 78 | C45: solid | D45: 5 | E45: 200 | F45: Spool | G45: =(H45/100) -> 2.7811875 | H45: 278.11875
B46: D-Power 78 | C46: solid | D46: 6 | E46: 200 | F46: Spool | G46: =(H46/100) -> 4.2801281 | H46: 428.01281
B48: V-Core
B49: V-Core | C49: solid natural | D49: 3 | E49: 200 | F49: Spool | G49: =(H49/100) -> 1.4525902 | H49: 145.25902
B50: V-Core | C50: solid natural | D50: 4 | E50: 200 | F50: Spool | G50: =(H50/100) -> 1.723025 | H50: 172.3025
B51: V-Core | C51: solid natural | D51: 5 | E51: 200 | F51: Spool | G51: =(H51/100) -> 3.262875 | H51: 326.2875
B52: V-Core | C52: solid natural | D52: 6 | E52: 200 | F52: Spool | G52: =(H52/100) -> 4.338 | H52: 433.8
B54: D-Cup 78
B55: D-Cup 78 | C55: mix grey + colour | D55: 4 | E55: 200 | F55: Spool | G55: =(H55/100) -> 2.0061458 | H55: 200.61458
B56: D-Cup 78 | C56: mix grey + colour | D56: 5 | E56: 200 | F56: Spool | G56: =(H56/100) -> 2.4776644 | H56: 247.76644
B57: D-Cup 78 | C57: mix grey + colour | D57: 6 | E57: 200 | F57: Spool | G57: =(H57/100) -> 2.5992488 | H57: 259.92488
B58: D-Cup 78 | C58: mix grey + colour | D58: 7 | E58: 200 | F58: Spool | G58: =(H58/100) -> 3.1206051 | H58: 312.06051
B59: D-Cup 78 | C59: mix grey + colour | D59: 8 | E59: 200 | F59: Spool | G59: =(H59/100) -> 5.1452746 | H59: 514.52746
B60: D-Cup 78 | C60: mix grey + colour | D60: 9 | E60: 200 | F60: Spool | G60: =(H60/100) -> 6.0762966 | H60: 607.62966
B61: D-Cup 78 | C61: mix grey + colour | D61: 10 | E61: 200 | F61: Spool | G61: =(H61/100) -> 6.8358508 | H61: 683.58508
B63: D-Cup 78 Kmix
...

Sheet Sailmaker
B10: ='Pro Race'!B11 -> PRICE LIST
B11: ='Pro Race'!B12 -> ref. 01-2017
B13: ='Pro Race'!B14 -> prices are ex-taxes and can be changed without prior notice
B14: ='Pro Race'!B15 -> position EXW Factory Portugal
B15: ='Pro Race'!B16 -> alpha ropes®
B16: ='Pro Race'!B17 -> valid from January 1st, 2017
B24: SAILMAKER | G24: Suggested Retail Price
B26: Product | C26: Colour | D26: Diam. | E26: Mts | G26: ='Pro Race'!G26 -> Retail €/mt | H26: ='Pro Race'!H26 -> Retail €/100mt
B27: D-Core 78
B28: D-Core 78 | C28: solid | D28: 2.5 | E28: 200 | F28: Spool | G28: =(H28/100) -> 0.8303175 | H28: 83.03175
B29: D-Core 78 | C29: solid | D29: 3 | E29: 200 | F29: Spool | G29: =(H29/100) -> 1.3127813 | H29: 131.27813
B30: D-Core 78 | C30: solid | D30: 4 | E30: 200 | F30: Spool | G30: =(H30/100) -> 1.8109014 | H30: 181.09014
B31: D-Core 78 | C31: solid | D31: 5 | E31: 200 | F31: Spool | G31: =(H31/100) -> 3.423 | H31: 342.3
B32: D-Core 78 | C32: solid | D32: 6 | E32: 200 | F32: Spool | G32: =(H32/100) -> 4.62495 | H32: 462.495
B33: D-Core 78 | C33: solid | D33: 7 | E33: 200 | F33: Spool | G33: =(H33/100) -> 5.8863 | H33: 588.63
B34: D-Core 78 | C34: solid | D34: 8 | E34: 200 | F34: Spool | G34: =(H34/100) -> 8.1505125 | H34: 815.05125
B35: D-Core 78 | C35: solid | D35: 9 | E35: 200 | F35: Spool | G35: =(H35/100) -> 11.076337 | H35: 1107.6337
B36: D-Core 78 | C36: solid | D36: 10 | E36: 200 | F36: Spool | G36: =(H36/100) -> 12.748238 | H36: 1274.8238
B37: D-Core 78 | C37: solid | D37: 12 | E37: 200 | F37: Spool | G37: =(H37/100) -> 14.538261 | H37: 1453.8261
B38: D-Core 78 | C38: solid | D38: 14 | E38: 100 | F38: Spool | G38: =(H38/100) -> 16.411622 | H38: 1641.1622
B39: D-Core 78 | C39: solid | D39: 16 | E39: 100 | F39: Spool | G39: =(H39/100) -> 21.882162 | H39: 2188.2162
... B44: D-Core 78 | C44: solid | D44: 26 | E44: 100 | F44: Spool | G44: =(H44/100) -> 51.24073 | H44: 5124.073
B46: V-Core
B47: V-Core | C47: solid natural | D47: 3 | E47: 200 | F47: Spool | G47: =(H47/100) -> 1.4525902 | H47: 145.25902
B48: V-Core | C48: solid natural | D48: 4 | E48: 200 | F48: Spool | G48: =(H48/100) -> 1.723025 | H48: 172.3025
B49: V-Core | C49: solid natural | D49: 5 | E49: 200 | F49: Spool | G49: =(H49/100) -> 3.262875 | H49: 326.2875
B50: V-Core | C50: solid natural | D50: 6 | E50: 200 | F50: Spool | G50: =(H50/100) -> 4.338 | H50: 433.8
B51: V-Core | C51: solid natural | D51: 7 | E51: 200 | F51: Spool | G51: =(H51/100) -> 5.6394 | H51: 563.94
B52: V-Core | C52: solid natural | D52: 8 | E52: 200 | F52: Spool | G52: =(H52/100) -> 7.741575 | H52: 774.1575
B53: V-Core | C53: solid natural | D53: 9 | E53: 200 | F53: Spool | G53: =(H53/100) -> 10.809533 | H53: 1080.9533
B54: V-Core | C54: solid natural | D54: 10 | E54: 200 | F54: Spool | G54: =(H54/100) -> 12.6159 | H54: 1261.59
B55: V-Core | C55: solid natural | D55: 12 | E55: 200 | F55: Spool | G55: =(H55/100) -> 15.339788 | H55: 1533.9788
B56: V-Core | C56: solid natural | D56: 14 | E56: 100 | F56: Spool | G56: =(H56/100) -> 18.007125 | H56: 1800.7125
B57: V-Core | C57: solid natural | D57: 16 | E57: 100 | F57: Spool | G57: =(H57/100) -> 24.832406 | H57: 2483.2406
B59: Ultraneema
B60: Ultraneema | C60: white + colour | D60: 1.6 | E60: 200 | F60: Spool | G60: =(H60/100) -> 0.20081111 | H60: 20.081111
B61: Ultraneema | C61: white + colour | D61: 2 | E61: 200 | F61: Spool | G61: =(H61/100) -> 0.23969898 | H61: 23.969898
B62: Ultraneema | C62: white + colour | D62: 2.5 | E62: 200 | F62: Spool | G62: =(H62/100) -> 0.32530576 | H62: 32.530576
B63: Ultraneema | C63: white + colour | D63: 3 | E63: 200 | F63: Spool | G63: =(H63/100) -> 0.76591525 | H63: 76.591525
B64: Ultraneema | C64: white + colour | D64: 4 | E64: 200 | F64: Spool | G64: =(H64/100) -> 1.5100966 | H64: 151.00966
...

Sheet Kite & Wind
B10: ='Pro Race'!B11 -> PRICE LIST
B11: ='Pro Race'!B12 -> ref. 01-2017
B13: ='Pro Race'!B14 -> prices are ex-taxes and can be changed without prior notice
B14: ='Pro Race'!B15 -> position EXW Factory Portugal
B15: ='Pro Race'!B16 -> alpha ropes®
B16: ='Pro Race'!B17 -> valid from January 1st, 2017
B24: KITE | G24: Suggested Retail Price
B26: Product | C26: Colour | D26: Diam. | E26: Mts | G26: ='Pro Race'!G26 -> Retail €/mt | H26: ='Pro Race'!H26 -> Retail €/100mt
B27: D-Core 78
B28: D-Core 78 | C28: solid | D28: 2.5 | E28: 200 | F28: Spool | G28: =(H28/100) -> 0.8303175 | H28: 83.03175
B29: D-Core 78 | C29: solid | D29: 3 | E29: 200 | F29: Spool | G29: =(H29/100) -> 1.3127813 | H29: 131.27813
B30: D-Core 78 | C30: solid | D30: 4 | E30: 200 | F30: Spool | G30: =(H30/100) -> 1.8109014 | H30: 181.09014
B31: D-Core 78 | C31: solid | D31: 5 | E31: 200 | F31: Spool | G31: =(H31/100) -> 3.423 | H31: 342.3
B32: D-Core 78 | C32: solid | D32: 6 | E32: 200 | F32: Spool | G32: =(H32/100) -> 4.62495 | H32: 462.495
B33: D-Core 78 | C33: solid | D33: 7 | E33: 200 | F33: Spool | G33: =(H33/100) -> 5.8863 | H33: 588.63
B34: D-Core 78 | C34: solid | D34: 8 | E34: 200 | F34: Spool | G34: =(H34/100) -> 8.1505125 | H34: 815.05125
B36: D-Power 78
B37: D-Power 78 | C37: solid | D37: 5 | E37: 200 | F37: Spool | G37: =(H37/100) -> 2.7811875 | H37: 278.11875
B39: Windsurf Line
B40: Windsurf Line | C40: white | D40: 3.8 | E40: 200 | F40: Spool | G40: =(H40/100) -> 2.5013778 | H40: 250.13778
B42: Kite Line 8-78
B43: Kite Line 8-78 | C43: white | D43: 1.7 | E43: 200 | F43: Spool | G43: =(H43/100) -> 0.59837288 | H43: 59.837288
B45: Kite Line 8-99
B46: Kite Line 8-99 | C46: white | D46: 1 | E46: 200 | F46: Spool | G46: =(H46/100) -> 0.42305085 | H46: 42.305085
B47: Kite Line 8-99 | C47: white | D47: 1.7 | E47: 200 | F47: Spool | G47: =(H47/100) -> 0.70649492 | H47: 70.649492
B49: Kite Line 12-99
B50: Kite Line 12-99 | C50: white | D50: 1.3 | E50: 200 | F50: Spool | G50: =(H50/100) -> 0.57819661 | H50: 57.819661
B52: Skincover Kite Line
B53: Skincover Kite Line | C53: solid colour | D53: 3 | E53: 200 | F53: Spool | G53: =(H53/100) -> 0.28972653 | H53: 28.972653

Sheet Mooring
B10: ='Pro Race'!B11 -> PRICE LIST
B11: ='Pro Race'!B12 -> ref. 01-2017
B13: ='Pro Race'!B14 -> prices are ex-taxes and can be changed without prior notice
B14: ='Pro Race'!B15 -> position EXW Factory Portugal
B15: ='Pro Race'!B16 -> alpha ropes®
B16: ='Pro Race'!B17 -> valid from January 1st, 2017
B24: MOORING | G24: Suggested Retail Price
B26: Product | C26: Colour | D26: Diam. | E26: Mts | G26: ='Pro Race'!G26 -> Retail €/mt | H26: ='Pro Race'!H26 -> Retail €/100mt
B27: Superior Polyester
B28: Superior Polyester | C28: white | D28: 4 | E28: 200 | F28: Spool | G28: =(H28/100) -> 0.22792865 | H28: 22.792865
B29: Superior Polyester | C29: white | D29: 5 | E29: 200 | F29: Spool | G29: =(H29/100) -> 0.37988108 | H29: 37.988108
B30: Superior Polyester | C30: white | D30: 6 | E30: 200 | F30: Spool | G30: =(H30/100) -> 0.49384541 | H30: 49.384541
B31: Superior Polyester | C31: white | D31: 8 | E31: 200 | F31: Spool | G31: =(H31/100) -> 0.65062763 | H31: 65.062763
B32: Superior Polyester | C32: white | D32: 10 | E32: 200 | F32: Spool | G32: =(H32/100) -> 1.0170982 | H32: 101.70982
B33: Superior Polyester | C33: white | D33: 12 | E33: 200 | F33: Spool | G33: =(H33/100) -> 1.4533236 | H33: 145.33236
B34: Superior Polyester | C34: white | D34: 14 | E34: 200 | F34: Spool | G34: =(H34/100) -> 1.8547228 | H34: 185.47228
B35: Superior Polyester | C35: white | D35: 16 | E35: 100 | F35: Spool | G35: =(H35/100) -> 2.3479641 | H35: 234.79641
B36: Superior Polyester | C36: white | D36: 18 | E36: 100 | F36: Spool | G36: =(H36/100) -> 3.0647047 | H36: 306.47047
B37: Superior Polyester | C37: white | D37: 20 | E37: 100 | F37: Coil | G37: =(H37/100) -> 3.7814044 | H37: 378.14044
B38: Superior Polyester | C38: white | D38: 22 | E38: 100 | F38: Coil | G38: =(H38/100) -> 3.8675906 | H38: 386.75906
B39: Superior Polyester | C39: white | D39: 24 | E39: 100 | F39: Coil | G39: =(H39/100) -> 4.310775 | H39: 431.0775
... B52: Superior Polyester | C52: colour | D52: 26 | E52: 100 | F52: Coil | G52: =(H52/100) -> 5.6272985 | H52: 562.72985
B54: Mooring | C54: PES cover / PA core
B55: Mooring | C55: solid colours | D55: 8 | E55: 200 | F55: Spool | G55: =(H55/100) -> 1.0868797 | H55: 108.68797
B56: Mooring | C56: solid colours | D56: 12 | E56: 200 | F56: Spool | G56: =(H56/100) -> 1.9114932 | H56: 191.14932
B57: Mooring | C57: solid colours | D57: 15 | E57: 100 | F57: Spool | G57: =(H57/100) -> 2.5248356 | H57: 252.48356
B58: Mooring | C58: solid colours | D58: 19 | E58: 100 | F58: Spool | G58: =(H58/100) -> 3.8424814 | H58: 384.24814
B59: Mooring | C59: solid colours | D59: 22 | E59: 100 | F59: Spool | G59: =(H59/100) -> 5.7637525 | H59: 576.37525
B60: Mooring | C60: solid colours | D60: 24 | E60: 100 | F60: Spool | G60: =(H60/100) -> 6.8365678 | H60: 683.65678
B61: Mooring | C61: solid colours | D61: 38 | E61: 100 | F61: Spool | G61: =(H61/100) -> 17.123261 | H61: 1712.3261
B62: Mooring | C62: solid colours | D62: 40 | E62: 100 | F62: Spool | G62: =(H62/100) -> 20.705 | H62: 2070.5
B64: Dockline | C64: PES cover / PES core
B65: Dockline | C65: solid colours | D65: 8 | E65: 200 | F65: Spool | G65: =(H65/100) -> 1.1690847 | H65: 116.90847
B66: Dockline | C66: solid colours | D66: 10 | E66: 200 | F66: Spool | G66: =(H66/100) -> 1.625339 | H66: 162.5339
B67: Dockline | C67: solid colours | D67: 12 | E67: 200 | F67: Spool | G67: =(H67/100) -> 1.7874915 | H67: 178.74915
B68: Dockline | C68: solid colours | D68: 14 | E68: 200 | F68: Spool | G68: =(H68/100) -> 2.4230441 | H68: 242.30441
B69: Dockline | C69: solid colours | D69: 16 | E69: 100 | F69: Spool | G69: =(H69/100) -> 2.9629831 | H69: 296.29831
B70: Dockline | C70: solid colours | D70: 18 | E70: 100 | F70: Spool | G70: =(H70/100) -> 4.2615305 | H70: 426.15305
B71: Dockline | C71: solid colours | D71: 20 | E71: 100 | F71: Spool | G71: =(H71/100) -> 5.2674712 | H71: 526.74712
B72: Dockline | C72: solid colours | D72: 22 | E72: 100 | F72: Spool | G72: =(H72/100) -> 6.9414814 | H72: 694.14814
...

Sheet Mini-Boxes
B10: ='Pro Race'!B11 -> PRICE LIST
B11: ='Pro Race'!B12 -> ref. 01-2017
B13: ='Pro Race'!B14 -> prices are ex-taxes and can be changed without prior notice
B14: ='Pro Race'!B15 -> position EXW Factory Portugal
B15: ='Pro Race'!B16 -> alpha ropes®
B16: ='Pro Race'!B17 -> valid from January 1st, 2017
B24: BOXES | G24: Suggested Retail Price
B26: Product | D26: Diam. | E26: Mts | G26: Retail €/box
B28: S-BOX
B29: Whipping Twine Colors | C29: 12 x S spools | D29: 1.0mm | E29: 12 x 35mt | G29: 51.678571
B30: Whipping Twine White | C30: 12 x S spools | D30: 1.0mm | E30: 12 x 35mt | G30: 51.678571
B31: Whipping Twine Dyneema | C31: 12 x S spools | E31: 12 x 35mt | G31: 141.67857
B32: Flyneema 1.0mm | C32: 12 x S Spools | D32: 1.0mm | E32: 12 x 35mt | G32: 105.38009
B33: Flyneema 1.2mm | C33: 12 x S Spools | D33: 1.2mm | E33: 12 x 35mt | G33: 121.79886
B34: Kite Line 8-78 | C34: 12 x S Spools | E34: 12 x 35mt | G34: 282.62818
B35: Softline 3mm | C35: 4 x M spools | D35: 3mm | E35: 4 x 20mt | G35: 25.539038
B36: Trimstar 3mm | C36: 4 x M spools | D36: 3mm | E36: 4 x 20mt | G36: 34.862262
B37: Ultraneema 3mm | C37: 4 x M spools | D37: 3mm | E37: 4 x 20mt | G37: 70.718856
B38: D-Core 78 3mm | C38: 4 x M spools | D38: 3mm | E38: 4 x 16mt | G38: 95.990833
B40: OPTI BOX - S
B41: contents: | G41: 74.25
B42: 3 x Flyneema 1.2mm S spools
B43: 1 x Ultraneema 3mm M spool
B44: 1 x Ultraneema 6mm L spool

Sheet Acessories
B10: ='Pro Race'!B11 -> PRICE LIST
B11: ='Pro Race'!B12 -> ref. 01-2017
B13: ='Pro Race'!B14 -> prices are ex-taxes and can be changed without prior notice
B14: ='Pro Race'!B15 -> position EXW Factory Portugal
B15: ='Pro Race'!B16 -> alpha ropes®
B16: ='Pro Race'!B17 -> valid from January 1st, 2017
B24: ACESSORIES
B26: Product | G26: Net Price €/unit
B28: Alpha Ropes Dinghy Display | G28: 319.99801
B29: Alpha Ropes Dinghy Display with Ropes: | G29: 1005.7361
C30: Flyneema 1mm Blue | D30: 500mt
C31: Ultraneema 2mm Red | D31: 200mt
C32: Ultraneema 3mm Royal Blue | D32: 100mt
C33: Ultraneema 4mm Black | D33: 100mt
C34: Trimstar 3mm Green | D34: 100mt
C35: Trimstar 4mm Yellow | D35: 100mt
C36: D-Core 3mm Black | D36: 100mt
C37: SSR Light 8mm Royal Blue | D37: 100mt
C38: SSR 5mm Grey | D38: 100mt
C39: D-Cup Kmix 5mm Yellow | D39: 100mt
C40: D-Cup Kmix 6mm Royal Blue | D40: 100mt
C41: D-Cup Kmix 7mm Vermelho | D41: 100mt
B43: Alpha Ropes Shop Display - Single | G43: 425.88235
B44: Alpha Ropes Shop Display - Double | G44: 608.23529
B45: Selma Needles | G45: 39.001421
B46: D-Splicer Set - includes handle + 4 needles | G46: 29
B47: D-Splicer F10 | G47: 8.8461538
B48: D-Splicer F15 | G48: 9
B49: D-Splicer F20 | G49: 9.3076923
B50: D-Splicer F25 | G50: 9.6923077
B51: D-Scissor | G51: 30
B52: Whipping Twine Polyester 1.0mm x 500mt | D52: Any color (white, black red, blue) | G52: 14
B53: Whipping Twine Dyneema x 1500mt | D53: white | G53: 132.86
B54: Splicing Tape 15mm

Sheet Ready Made
B10: ='Pro Race'!B11 -> PRICE LIST
B11: ='Pro Race'!B12 -> ref. 01-2017
B13: ='Pro Race'!B14 -> prices are ex-taxes and can be changed without prior notice
B14: ='Pro Race'!B15 -> position EXW Factory Portugal
B15: ='Pro Race'!B16 -> alpha ropes®
B16: ='Pro Race'!B17 -> valid from January 1st, 2017
B28: READY MADE | G28: Suggested Retail Price
B30: Product | C30: Colour | D30: Diam. | E30: Mts | G30: Retail €/unit
B31: Dockline | C31: PES/PES
B32: Dockline | C32: white + Eye 200mm | D32: 8 | E32: 5 | F32: Unit | G32: 19.50555
B33: Dockline | C33: white + Eye 250mm | D33: 10 | E33: 6 | F33: Unit | G33: 23.567143
B34: Dockline | C34: white + Eye 250mm | D34: 10 | E34: 10 | F34: Unit | G34: 29.687143
B35: Dockline | C35: white + Eye 250mm | D35: 12 | E35: 7 | F35: Unit | G35: 26.09538
B36: Dockline | C36: white + Eye 250mm | D36: 12 | E36: 10 | F36: Unit | G36: 31.059719
B38: Dockline | C38: solid color + Eye 200mm | D38: 8 | E38: 5 | F38: Unit | G38: 19.871651
B39: Dockline | C39: solid color + Eye 250mm | D39: 10 | E39: 6 | F39: Unit | G39: 24.234516
B40: Dockline | C40: solid color + Eye 250mm | D40: 10 | E40: 10 | F40: Unit | G40: 30.735872
B41: Dockline | C41: solid color + Eye 250mm | D41: 12 | E41: 7 | F41: Unit | G41: 27.157075
B42: Dockline | C42: solid color + Eye 250mm | D42: 12 | E42: 10 | F42: Unit | G42: 32.51955
B44: Anchorline | C44: PES/PES
B45: Dockline Eye+M.Thimble | C45: white with Eye + Stain Thimble | D45: 10 | E45: 30 | F45: Unit | G45: 66.155714
B46: Dockline Eye+M.Thimble | C46: white with Eye + Stain Thimble | D46: 12 | E46: 30 | F46: Unit | G46: 71.583884
B47: Dockline Eye+M.Thimble | C47: white with Eye + Stain Thimble | D47: 14 | E47: 30 | F47: Unit | G47: 92.423233
B49: Dockline Eye+M.Thimble | C49: color with Eye + Stain Thimble | D49: 10 | E49: 30 | F49: Unit | G49: 69.111223
B50: Dockline Eye+M.Thimble | C50: color with Eye + Stain Thimble | D50: 12 | E50: 30 | F50: Unit | G50: 75.697952
B51: Dockline Eye+M.Thimble | C51: color with Eye + Stain Thimble | D51: 14 | E51: 30 | F51: Unit | G51: 98.00008
B53: Fender Line SUPERIOR | C53: 3 Strand PES
B54: Superior | C54: white + one eye 40mm | D54: 6 | E54: 1.5 | F54: Unit | G54: 8.7098666
B55: Superior | C55: white + one eye 40mm | D55: 6 | E55: 2 | F55: Unit | G55: 9.0232685
B56: Superior | C56: white + one eye 40mm | D56: 8 | E56: 1.5 | F56: Unit | G56: 8.5802903
B57: Superior | C57: white + one eye 40mm | D57: 8 | E57: 2 | F57: Unit | G57: 8.8677769
B58: Superior | C58: white + one eye 40mm | D58: 10 | E58: 2 | F58: Unit | G58: 10.74508
B60: Superior | C60: colour + one eye 40mm | D60: 6 | E60: 1.5 | F60: Unit | G60: 8.8539731
B61: Superior | C61: colour + one eye 40mm | D61: 6 | E61: 2 | F61: Unit | G61: 9.1961963
B62: Superior | C62: colour + one eye 40mm | D62: 8 | E62: 1.5 | F62: Unit | G62: 9.1215224
B63: Superior | C63: colour + one eye 40mm | D63: 8 | E63: 2 | F63: Unit | G63: 9.5172554
B64: Superior | C64: colour + one eye 40mm | D64: 10 | E64: 2 | F64: Unit | G64: 11.262211

Sheet Webbings
B10: ='Pro Race'!B11 -> PRICE LIST
B11: ='Pro Race'!B12 -> ref. 01-2017
B13: ='Pro Race'!B14 -> prices are ex-taxes and can be changed without prior notice
B14: ='Pro Race'!B15 -> position EXW Factory Portugal
B15: ='Pro Race'!B16 -> alpha ropes®
B16: ='Pro Race'!B17 -> valid from January 1st, 2017
B24: WEBBINGS | G24: Suggested Retail Price
B26: Product | G26: Retail €/mt | H26: Retail €/100mt
B27: Polyester Standard | C27: Bload
B28: 12mm | C28: 320kgf | D28: White | G28: =(H28/100) -> 0.27428571 | H28: 27.428571
B29: 20mm | C29: 500kgf | D29: White | G29: =(H29/100) -> 0.50857143 | H29: 50.857143
B30: 25mm | C30: 600kgf | D30: White | G30: =(H30/100) -> 0.53714286 | H30: 53.714286
B31: 30mm | C31: 850kgf | D31: White | G31: =(H31/100) -> 0.65714286 | H31: 65.714286
B33: Polyester Heavy Weight | C33: Bload
B34: 12mm | C34: 400kgf | D34: White | H34: 25.714286
B35: 12mm | C35: 400kgf | D35: Color | H35: 32.142857
B36: 20mm | C36: 500kgf | D36: White | G36: =(H36/100) -> 0.34285714 | H36: 34.285714
B37: 20mm | C37: 500kgf | D37: Color | G37: =(H37/100) -> 0.42857143 | H37: 42.857143
B38: 25mm | C38: 960kgf | D38: White | G38: =(H38/100) -> 0.42285714 | H38: 42.285714
B39: 25mm | C39: 960kgf | D39: Color | G39: =(H39/100) -> 0.52857143 | H39: 52.857143
B40: 30mm | C40: 1.100kgf | D40: White | G40: =(H40/100) -> 0.50285714 | H40: 50.285714
B41: 30mm | C41: 1.100kgf | D41: Color | G41: =(H41/100) -> 0.62857143 | H41: 62.857143
B42: 40mm | C42: 1.450kgf | D42: White | G42: =(H42/100) -> 0.65714286 | H42: 65.714286
B43: 40mm | C43: 1.450kgf | D43: Color | G43: =(H43/100) -> 0.82142857 | H43: 82.142857
B44: 50mm | C44: 1.800kgf | D44: White | G44: =(H44/100) -> 0.82857143 | H44: 82.857143
B45: 50mm | C45: 1.800kgf | D45: Color | G45: =(H45/100) -> 1.0357143 | H45: 103.57143
B46: 63mm | D46: White | G46: =(H46/100) -> 1 | H46: 100
B47: 63mm | D47: Color | G47: =(H47/100) -> 1.25 | H47: 125
B49: Polyester XT Heavy Weight | C49: Bload
B50: 25m | C50: 1.270kgf | D50: White | G50: =(H50/100) -> 0.8 | H50: 80
B51: 30mm | C51: 1.800kgf | D51: White | G51: =(H51/100) -> 0.94285714 | H51: 94.285714
B52: 40mm | C52: 2.400kgf | D52: White | G52: =(H52/100) -> 1.2571429 | H52: 125.71429
B53: 50mm | C53: 3.100kgf | D53: White | G53: =(H53/100) -> 1.4857143 | H53: 148.57143
B55: Polyester Extreme - Truck (para Doyle Sails USA) | C55: Bload
B56: 55mm | C56: 12.000kgf | D56: White | G56: =(H56/100) -> 4.6753247 | H56: 467.53247
B58: Polyester Tubular Super Heavy | C58: Bload
B59: 25mm | C59: 1.700kgf | D59: White | G59: =(H59/100) -> 0.74363992 | H59: 74.363992
B61: Polypropylene Standard
B62: 20mm | D62: White | G62: =(H62/100) -> 0.29142857 | H62: 29.142857
B63: 25mm | D63: White | G63: =(H63/100) -> 0.34285714 | H63: 34.285714
...

Sheet Folha1
